2025-08-04 19:36:41,594 - main - INFO - Starting Radius Core service...
2025-08-04 19:36:41,594 - redis_client - ERROR - Failed to connect to Redis: Redis URL must specify one of the following schemes (redis://, rediss://, unix://)
2025-08-04 19:36:41,594 - redis_client - ERROR - Redis health check failed: Redis URL must specify one of the following schemes (redis://, rediss://, unix://)
2025-08-04 19:36:41,594 - main - ERROR - Redis health check failed
2025-08-04 19:36:41,594 - aio_pika.robust_connection - INFO - Connection to  closed. Reconnecting after 5 seconds.
2025-08-04 19:36:41,594 - aio_pika.robust_connection - ERROR - Reconnect attempt failed . Retrying after 5 seconds.
Traceback (most recent call last):
  File "/home/data/freerad_api/.venv/lib/python3.13/site-packages/aio_pika/robust_connection.py", line 135, in __connection_factory
    await Connection.connect(self, self.__connect_timeout)
  File "/home/data/freerad_api/.venv/lib/python3.13/site-packages/aio_pika/connection.py", line 125, in connect
    self.transport = await UnderlayConnection.connect(
                     ^^^^^^^^^^^^^^^^^^^^^^^^^^^^^^^^^
    ...<2 lines>...
    )
    ^
  File "/home/data/freerad_api/.venv/lib/python3.13/site-packages/aio_pika/abc.py", line 679, in connect
    connection = await cls.make_connection(
                 ^^^^^^^^^^^^^^^^^^^^^^^^^^
        url, timeout=timeout, **kwargs,
        ^^^^^^^^^^^^^^^^^^^^^^^^^^^^^^^
    )
    ^
  File "/home/data/freerad_api/.venv/lib/python3.13/site-packages/aio_pika/abc.py", line 667, in make_connection
    connection: aiormq.abc.AbstractConnection = await asyncio.wait_for(
                                                ^^^^^^^^^^^^^^^^^^^^^^^
        aiormq.connect(url, **kwargs), timeout=timeout,
        ^^^^^^^^^^^^^^^^^^^^^^^^^^^^^^^^^^^^^^^^^^^^^^^
    )
    ^
  File "/root/.local/share/uv/python/cpython-3.13.5-linux-x86_64-gnu/lib/python3.13/asyncio/tasks.py", line 507, in wait_for
    return await fut
           ^^^^^^^^^
  File "/home/data/freerad_api/.venv/lib/python3.13/site-packages/aiormq/connection.py", line 920, in connect
    await connection.connect(client_properties or {})
  File "/home/data/freerad_api/.venv/lib/python3.13/site-packages/aiormq/base.py", line 164, in wrap
    return await self.create_task(func(self, *args, **kwargs))
           ^^^^^^^^^^^^^^^^^^^^^^^^^^^^^^^^^^^^^^^^^^^^^^^^^^^
  File "/home/data/freerad_api/.venv/lib/python3.13/site-packages/aiormq/abc.py", line 44, in __inner
    return await self.task
           ^^^^^^^^^^^^^^^
  File "/home/data/freerad_api/.venv/lib/python3.13/site-packages/aiormq/connection.py", line 457, in connect
    reader, writer = await asyncio.open_connection(
                     ^^^^^^^^^^^^^^^^^^^^^^^^^^^^^^
    ...<2 lines>...
    )
    ^
  File "/root/.local/share/uv/python/cpython-3.13.5-linux-x86_64-gnu/lib/python3.13/asyncio/streams.py", line 48, in open_connection
    transport, _ = await loop.create_connection(
                   ^^^^^^^^^^^^^^^^^^^^^^^^^^^^^
        lambda: protocol, host, port, **kwds)
        ^^^^^^^^^^^^^^^^^^^^^^^^^^^^^^^^^^^^^
  File "uvloop/loop.pyx", line 2050, in create_connection
ValueError: host and port was not specified and no sock specified
2025-08-04 19:36:46,596 - aio_pika.robust_connection - INFO - Connection to  closed. Reconnecting after 5 seconds.
2025-08-04 19:36:46,596 - aio_pika.robust_connection - ERROR - Reconnect attempt failed . Retrying after 5 seconds.
Traceback (most recent call last):
  File "/home/data/freerad_api/.venv/lib/python3.13/site-packages/aio_pika/robust_connection.py", line 135, in __connection_factory
    await Connection.connect(self, self.__connect_timeout)
  File "/home/data/freerad_api/.venv/lib/python3.13/site-packages/aio_pika/connection.py", line 125, in connect
    self.transport = await UnderlayConnection.connect(
                     ^^^^^^^^^^^^^^^^^^^^^^^^^^^^^^^^^
    ...<2 lines>...
    )
    ^
  File "/home/data/freerad_api/.venv/lib/python3.13/site-packages/aio_pika/abc.py", line 679, in connect
    connection = await cls.make_connection(
                 ^^^^^^^^^^^^^^^^^^^^^^^^^^
        url, timeout=timeout, **kwargs,
        ^^^^^^^^^^^^^^^^^^^^^^^^^^^^^^^
    )
    ^
  File "/home/data/freerad_api/.venv/lib/python3.13/site-packages/aio_pika/abc.py", line 667, in make_connection
    connection: aiormq.abc.AbstractConnection = await asyncio.wait_for(
                                                ^^^^^^^^^^^^^^^^^^^^^^^
        aiormq.connect(url, **kwargs), timeout=timeout,
        ^^^^^^^^^^^^^^^^^^^^^^^^^^^^^^^^^^^^^^^^^^^^^^^
    )
    ^
  File "/root/.local/share/uv/python/cpython-3.13.5-linux-x86_64-gnu/lib/python3.13/asyncio/tasks.py", line 507, in wait_for
    return await fut
           ^^^^^^^^^
  File "/home/data/freerad_api/.venv/lib/python3.13/site-packages/aiormq/connection.py", line 920, in connect
    await connection.connect(client_properties or {})
  File "/home/data/freerad_api/.venv/lib/python3.13/site-packages/aiormq/base.py", line 164, in wrap
    return await self.create_task(func(self, *args, **kwargs))
           ^^^^^^^^^^^^^^^^^^^^^^^^^^^^^^^^^^^^^^^^^^^^^^^^^^^
  File "/home/data/freerad_api/.venv/lib/python3.13/site-packages/aiormq/abc.py", line 44, in __inner
    return await self.task
           ^^^^^^^^^^^^^^^
  File "/home/data/freerad_api/.venv/lib/python3.13/site-packages/aiormq/connection.py", line 457, in connect
    reader, writer = await asyncio.open_connection(
                     ^^^^^^^^^^^^^^^^^^^^^^^^^^^^^^
    ...<2 lines>...
    )
    ^
  File "/root/.local/share/uv/python/cpython-3.13.5-linux-x86_64-gnu/lib/python3.13/asyncio/streams.py", line 48, in open_connection
    transport, _ = await loop.create_connection(
                   ^^^^^^^^^^^^^^^^^^^^^^^^^^^^^
        lambda: protocol, host, port, **kwds)
        ^^^^^^^^^^^^^^^^^^^^^^^^^^^^^^^^^^^^^
  File "uvloop/loop.pyx", line 2050, in create_connection
ValueError: host and port was not specified and no sock specified
2025-08-04 19:36:51,602 - aio_pika.robust_connection - INFO - Connection to  closed. Reconnecting after 5 seconds.
2025-08-04 19:36:51,602 - aio_pika.robust_connection - ERROR - Reconnect attempt failed . Retrying after 5 seconds.
Traceback (most recent call last):
  File "/home/data/freerad_api/.venv/lib/python3.13/site-packages/aio_pika/robust_connection.py", line 135, in __connection_factory
    await Connection.connect(self, self.__connect_timeout)
  File "/home/data/freerad_api/.venv/lib/python3.13/site-packages/aio_pika/connection.py", line 125, in connect
    self.transport = await UnderlayConnection.connect(
                     ^^^^^^^^^^^^^^^^^^^^^^^^^^^^^^^^^
    ...<2 lines>...
    )
    ^
  File "/home/data/freerad_api/.venv/lib/python3.13/site-packages/aio_pika/abc.py", line 679, in connect
    connection = await cls.make_connection(
                 ^^^^^^^^^^^^^^^^^^^^^^^^^^
        url, timeout=timeout, **kwargs,
        ^^^^^^^^^^^^^^^^^^^^^^^^^^^^^^^
    )
    ^
  File "/home/data/freerad_api/.venv/lib/python3.13/site-packages/aio_pika/abc.py", line 667, in make_connection
    connection: aiormq.abc.AbstractConnection = await asyncio.wait_for(
                                                ^^^^^^^^^^^^^^^^^^^^^^^
        aiormq.connect(url, **kwargs), timeout=timeout,
        ^^^^^^^^^^^^^^^^^^^^^^^^^^^^^^^^^^^^^^^^^^^^^^^
    )
    ^
  File "/root/.local/share/uv/python/cpython-3.13.5-linux-x86_64-gnu/lib/python3.13/asyncio/tasks.py", line 507, in wait_for
    return await fut
           ^^^^^^^^^
  File "/home/data/freerad_api/.venv/lib/python3.13/site-packages/aiormq/connection.py", line 920, in connect
    await connection.connect(client_properties or {})
  File "/home/data/freerad_api/.venv/lib/python3.13/site-packages/aiormq/base.py", line 164, in wrap
    return await self.create_task(func(self, *args, **kwargs))
           ^^^^^^^^^^^^^^^^^^^^^^^^^^^^^^^^^^^^^^^^^^^^^^^^^^^
  File "/home/data/freerad_api/.venv/lib/python3.13/site-packages/aiormq/abc.py", line 44, in __inner
    return await self.task
           ^^^^^^^^^^^^^^^
  File "/home/data/freerad_api/.venv/lib/python3.13/site-packages/aiormq/connection.py", line 457, in connect
    reader, writer = await asyncio.open_connection(
                     ^^^^^^^^^^^^^^^^^^^^^^^^^^^^^^
    ...<2 lines>...
    )
    ^
  File "/root/.local/share/uv/python/cpython-3.13.5-linux-x86_64-gnu/lib/python3.13/asyncio/streams.py", line 48, in open_connection
    transport, _ = await loop.create_connection(
                   ^^^^^^^^^^^^^^^^^^^^^^^^^^^^^
        lambda: protocol, host, port, **kwds)
        ^^^^^^^^^^^^^^^^^^^^^^^^^^^^^^^^^^^^^
  File "uvloop/loop.pyx", line 2050, in create_connection
ValueError: host and port was not specified and no sock specified
2025-08-04 19:36:56,605 - aio_pika.robust_connection - INFO - Connection to  closed. Reconnecting after 5 seconds.
2025-08-04 19:36:56,605 - aio_pika.robust_connection - ERROR - Reconnect attempt failed . Retrying after 5 seconds.
Traceback (most recent call last):
  File "/home/data/freerad_api/.venv/lib/python3.13/site-packages/aio_pika/robust_connection.py", line 135, in __connection_factory
    await Connection.connect(self, self.__connect_timeout)
  File "/home/data/freerad_api/.venv/lib/python3.13/site-packages/aio_pika/connection.py", line 125, in connect
    self.transport = await UnderlayConnection.connect(
                     ^^^^^^^^^^^^^^^^^^^^^^^^^^^^^^^^^
    ...<2 lines>...
    )
    ^
  File "/home/data/freerad_api/.venv/lib/python3.13/site-packages/aio_pika/abc.py", line 679, in connect
    connection = await cls.make_connection(
                 ^^^^^^^^^^^^^^^^^^^^^^^^^^
        url, timeout=timeout, **kwargs,
        ^^^^^^^^^^^^^^^^^^^^^^^^^^^^^^^
    )
    ^
  File "/home/data/freerad_api/.venv/lib/python3.13/site-packages/aio_pika/abc.py", line 667, in make_connection
    connection: aiormq.abc.AbstractConnection = await asyncio.wait_for(
                                                ^^^^^^^^^^^^^^^^^^^^^^^
        aiormq.connect(url, **kwargs), timeout=timeout,
        ^^^^^^^^^^^^^^^^^^^^^^^^^^^^^^^^^^^^^^^^^^^^^^^
    )
    ^
  File "/root/.local/share/uv/python/cpython-3.13.5-linux-x86_64-gnu/lib/python3.13/asyncio/tasks.py", line 507, in wait_for
    return await fut
           ^^^^^^^^^
  File "/home/data/freerad_api/.venv/lib/python3.13/site-packages/aiormq/connection.py", line 920, in connect
    await connection.connect(client_properties or {})
  File "/home/data/freerad_api/.venv/lib/python3.13/site-packages/aiormq/base.py", line 164, in wrap
    return await self.create_task(func(self, *args, **kwargs))
           ^^^^^^^^^^^^^^^^^^^^^^^^^^^^^^^^^^^^^^^^^^^^^^^^^^^
  File "/home/data/freerad_api/.venv/lib/python3.13/site-packages/aiormq/abc.py", line 44, in __inner
    return await self.task
           ^^^^^^^^^^^^^^^
  File "/home/data/freerad_api/.venv/lib/python3.13/site-packages/aiormq/connection.py", line 457, in connect
    reader, writer = await asyncio.open_connection(
                     ^^^^^^^^^^^^^^^^^^^^^^^^^^^^^^
    ...<2 lines>...
    )
    ^
  File "/root/.local/share/uv/python/cpython-3.13.5-linux-x86_64-gnu/lib/python3.13/asyncio/streams.py", line 48, in open_connection
    transport, _ = await loop.create_connection(
                   ^^^^^^^^^^^^^^^^^^^^^^^^^^^^^
        lambda: protocol, host, port, **kwds)
        ^^^^^^^^^^^^^^^^^^^^^^^^^^^^^^^^^^^^^
  File "uvloop/loop.pyx", line 2050, in create_connection
ValueError: host and port was not specified and no sock specified
2025-08-04 19:37:01,607 - aio_pika.robust_connection - INFO - Connection to  closed. Reconnecting after 5 seconds.
2025-08-04 19:37:01,607 - aio_pika.robust_connection - ERROR - Reconnect attempt failed . Retrying after 5 seconds.
Traceback (most recent call last):
  File "/home/data/freerad_api/.venv/lib/python3.13/site-packages/aio_pika/robust_connection.py", line 135, in __connection_factory
    await Connection.connect(self, self.__connect_timeout)
  File "/home/data/freerad_api/.venv/lib/python3.13/site-packages/aio_pika/connection.py", line 125, in connect
    self.transport = await UnderlayConnection.connect(
                     ^^^^^^^^^^^^^^^^^^^^^^^^^^^^^^^^^
    ...<2 lines>...
    )
    ^
  File "/home/data/freerad_api/.venv/lib/python3.13/site-packages/aio_pika/abc.py", line 679, in connect
    connection = await cls.make_connection(
                 ^^^^^^^^^^^^^^^^^^^^^^^^^^
        url, timeout=timeout, **kwargs,
        ^^^^^^^^^^^^^^^^^^^^^^^^^^^^^^^
    )
    ^
  File "/home/data/freerad_api/.venv/lib/python3.13/site-packages/aio_pika/abc.py", line 667, in make_connection
    connection: aiormq.abc.AbstractConnection = await asyncio.wait_for(
                                                ^^^^^^^^^^^^^^^^^^^^^^^
        aiormq.connect(url, **kwargs), timeout=timeout,
        ^^^^^^^^^^^^^^^^^^^^^^^^^^^^^^^^^^^^^^^^^^^^^^^
    )
    ^
  File "/root/.local/share/uv/python/cpython-3.13.5-linux-x86_64-gnu/lib/python3.13/asyncio/tasks.py", line 507, in wait_for
    return await fut
           ^^^^^^^^^
  File "/home/data/freerad_api/.venv/lib/python3.13/site-packages/aiormq/connection.py", line 920, in connect
    await connection.connect(client_properties or {})
  File "/home/data/freerad_api/.venv/lib/python3.13/site-packages/aiormq/base.py", line 164, in wrap
    return await self.create_task(func(self, *args, **kwargs))
           ^^^^^^^^^^^^^^^^^^^^^^^^^^^^^^^^^^^^^^^^^^^^^^^^^^^
  File "/home/data/freerad_api/.venv/lib/python3.13/site-packages/aiormq/abc.py", line 44, in __inner
    return await self.task
           ^^^^^^^^^^^^^^^
  File "/home/data/freerad_api/.venv/lib/python3.13/site-packages/aiormq/connection.py", line 457, in connect
    reader, writer = await asyncio.open_connection(
                     ^^^^^^^^^^^^^^^^^^^^^^^^^^^^^^
    ...<2 lines>...
    )
    ^
  File "/root/.local/share/uv/python/cpython-3.13.5-linux-x86_64-gnu/lib/python3.13/asyncio/streams.py", line 48, in open_connection
    transport, _ = await loop.create_connection(
                   ^^^^^^^^^^^^^^^^^^^^^^^^^^^^^
        lambda: protocol, host, port, **kwds)
        ^^^^^^^^^^^^^^^^^^^^^^^^^^^^^^^^^^^^^
  File "uvloop/loop.pyx", line 2050, in create_connection
ValueError: host and port was not specified and no sock specified
2025-08-04 20:02:38,514 - main - INFO - Starting Radius Core service...
2025-08-04 20:02:38,515 - redis_client - ERROR - Failed to connect to Redis: Redis URL must specify one of the following schemes (redis://, rediss://, unix://)
2025-08-04 20:02:38,515 - redis_client - ERROR - Redis health check failed: Redis URL must specify one of the following schemes (redis://, rediss://, unix://)
2025-08-04 20:02:38,515 - main - ERROR - Redis health check failed
2025-08-04 20:02:38,515 - aio_pika.robust_connection - INFO - Connection to  closed. Reconnecting after 5 seconds.
2025-08-04 20:02:38,515 - aio_pika.robust_connection - ERROR - Reconnect attempt failed . Retrying after 5 seconds.
Traceback (most recent call last):
  File "/home/data/freerad_api/.venv/lib/python3.13/site-packages/aio_pika/robust_connection.py", line 135, in __connection_factory
    await Connection.connect(self, self.__connect_timeout)
  File "/home/data/freerad_api/.venv/lib/python3.13/site-packages/aio_pika/connection.py", line 125, in connect
    self.transport = await UnderlayConnection.connect(
                     ^^^^^^^^^^^^^^^^^^^^^^^^^^^^^^^^^
    ...<2 lines>...
    )
    ^
  File "/home/data/freerad_api/.venv/lib/python3.13/site-packages/aio_pika/abc.py", line 679, in connect
    connection = await cls.make_connection(
                 ^^^^^^^^^^^^^^^^^^^^^^^^^^
        url, timeout=timeout, **kwargs,
        ^^^^^^^^^^^^^^^^^^^^^^^^^^^^^^^
    )
    ^
  File "/home/data/freerad_api/.venv/lib/python3.13/site-packages/aio_pika/abc.py", line 667, in make_connection
    connection: aiormq.abc.AbstractConnection = await asyncio.wait_for(
                                                ^^^^^^^^^^^^^^^^^^^^^^^
        aiormq.connect(url, **kwargs), timeout=timeout,
        ^^^^^^^^^^^^^^^^^^^^^^^^^^^^^^^^^^^^^^^^^^^^^^^
    )
    ^
  File "/root/.local/share/uv/python/cpython-3.13.5-linux-x86_64-gnu/lib/python3.13/asyncio/tasks.py", line 507, in wait_for
    return await fut
           ^^^^^^^^^
  File "/home/data/freerad_api/.venv/lib/python3.13/site-packages/aiormq/connection.py", line 920, in connect
    await connection.connect(client_properties or {})
  File "/home/data/freerad_api/.venv/lib/python3.13/site-packages/aiormq/base.py", line 164, in wrap
    return await self.create_task(func(self, *args, **kwargs))
           ^^^^^^^^^^^^^^^^^^^^^^^^^^^^^^^^^^^^^^^^^^^^^^^^^^^
  File "/home/data/freerad_api/.venv/lib/python3.13/site-packages/aiormq/abc.py", line 44, in __inner
    return await self.task
           ^^^^^^^^^^^^^^^
  File "/home/data/freerad_api/.venv/lib/python3.13/site-packages/aiormq/connection.py", line 457, in connect
    reader, writer = await asyncio.open_connection(
                     ^^^^^^^^^^^^^^^^^^^^^^^^^^^^^^
    ...<2 lines>...
    )
    ^
  File "/root/.local/share/uv/python/cpython-3.13.5-linux-x86_64-gnu/lib/python3.13/asyncio/streams.py", line 48, in open_connection
    transport, _ = await loop.create_connection(
                   ^^^^^^^^^^^^^^^^^^^^^^^^^^^^^
        lambda: protocol, host, port, **kwds)
        ^^^^^^^^^^^^^^^^^^^^^^^^^^^^^^^^^^^^^
  File "uvloop/loop.pyx", line 2050, in create_connection
ValueError: host and port was not specified and no sock specified
2025-08-04 20:02:43,518 - aio_pika.robust_connection - INFO - Connection to  closed. Reconnecting after 5 seconds.
2025-08-04 20:02:43,518 - aio_pika.robust_connection - ERROR - Reconnect attempt failed . Retrying after 5 seconds.
Traceback (most recent call last):
  File "/home/data/freerad_api/.venv/lib/python3.13/site-packages/aio_pika/robust_connection.py", line 135, in __connection_factory
    await Connection.connect(self, self.__connect_timeout)
  File "/home/data/freerad_api/.venv/lib/python3.13/site-packages/aio_pika/connection.py", line 125, in connect
    self.transport = await UnderlayConnection.connect(
                     ^^^^^^^^^^^^^^^^^^^^^^^^^^^^^^^^^
    ...<2 lines>...
    )
    ^
  File "/home/data/freerad_api/.venv/lib/python3.13/site-packages/aio_pika/abc.py", line 679, in connect
    connection = await cls.make_connection(
                 ^^^^^^^^^^^^^^^^^^^^^^^^^^
        url, timeout=timeout, **kwargs,
        ^^^^^^^^^^^^^^^^^^^^^^^^^^^^^^^
    )
    ^
  File "/home/data/freerad_api/.venv/lib/python3.13/site-packages/aio_pika/abc.py", line 667, in make_connection
    connection: aiormq.abc.AbstractConnection = await asyncio.wait_for(
                                                ^^^^^^^^^^^^^^^^^^^^^^^
        aiormq.connect(url, **kwargs), timeout=timeout,
        ^^^^^^^^^^^^^^^^^^^^^^^^^^^^^^^^^^^^^^^^^^^^^^^
    )
    ^
  File "/root/.local/share/uv/python/cpython-3.13.5-linux-x86_64-gnu/lib/python3.13/asyncio/tasks.py", line 507, in wait_for
    return await fut
           ^^^^^^^^^
  File "/home/data/freerad_api/.venv/lib/python3.13/site-packages/aiormq/connection.py", line 920, in connect
    await connection.connect(client_properties or {})
  File "/home/data/freerad_api/.venv/lib/python3.13/site-packages/aiormq/base.py", line 164, in wrap
    return await self.create_task(func(self, *args, **kwargs))
           ^^^^^^^^^^^^^^^^^^^^^^^^^^^^^^^^^^^^^^^^^^^^^^^^^^^
  File "/home/data/freerad_api/.venv/lib/python3.13/site-packages/aiormq/abc.py", line 44, in __inner
    return await self.task
           ^^^^^^^^^^^^^^^
  File "/home/data/freerad_api/.venv/lib/python3.13/site-packages/aiormq/connection.py", line 457, in connect
    reader, writer = await asyncio.open_connection(
                     ^^^^^^^^^^^^^^^^^^^^^^^^^^^^^^
    ...<2 lines>...
    )
    ^
  File "/root/.local/share/uv/python/cpython-3.13.5-linux-x86_64-gnu/lib/python3.13/asyncio/streams.py", line 48, in open_connection
    transport, _ = await loop.create_connection(
                   ^^^^^^^^^^^^^^^^^^^^^^^^^^^^^
        lambda: protocol, host, port, **kwds)
        ^^^^^^^^^^^^^^^^^^^^^^^^^^^^^^^^^^^^^
  File "uvloop/loop.pyx", line 2050, in create_connection
ValueError: host and port was not specified and no sock specified
2025-08-04 20:02:48,522 - aio_pika.robust_connection - INFO - Connection to  closed. Reconnecting after 5 seconds.
2025-08-04 20:02:48,522 - aio_pika.robust_connection - ERROR - Reconnect attempt failed . Retrying after 5 seconds.
Traceback (most recent call last):
  File "/home/data/freerad_api/.venv/lib/python3.13/site-packages/aio_pika/robust_connection.py", line 135, in __connection_factory
    await Connection.connect(self, self.__connect_timeout)
  File "/home/data/freerad_api/.venv/lib/python3.13/site-packages/aio_pika/connection.py", line 125, in connect
    self.transport = await UnderlayConnection.connect(
                     ^^^^^^^^^^^^^^^^^^^^^^^^^^^^^^^^^
    ...<2 lines>...
    )
    ^
  File "/home/data/freerad_api/.venv/lib/python3.13/site-packages/aio_pika/abc.py", line 679, in connect
    connection = await cls.make_connection(
                 ^^^^^^^^^^^^^^^^^^^^^^^^^^
        url, timeout=timeout, **kwargs,
        ^^^^^^^^^^^^^^^^^^^^^^^^^^^^^^^
    )
    ^
  File "/home/data/freerad_api/.venv/lib/python3.13/site-packages/aio_pika/abc.py", line 667, in make_connection
    connection: aiormq.abc.AbstractConnection = await asyncio.wait_for(
                                                ^^^^^^^^^^^^^^^^^^^^^^^
        aiormq.connect(url, **kwargs), timeout=timeout,
        ^^^^^^^^^^^^^^^^^^^^^^^^^^^^^^^^^^^^^^^^^^^^^^^
    )
    ^
  File "/root/.local/share/uv/python/cpython-3.13.5-linux-x86_64-gnu/lib/python3.13/asyncio/tasks.py", line 507, in wait_for
    return await fut
           ^^^^^^^^^
  File "/home/data/freerad_api/.venv/lib/python3.13/site-packages/aiormq/connection.py", line 920, in connect
    await connection.connect(client_properties or {})
  File "/home/data/freerad_api/.venv/lib/python3.13/site-packages/aiormq/base.py", line 164, in wrap
    return await self.create_task(func(self, *args, **kwargs))
           ^^^^^^^^^^^^^^^^^^^^^^^^^^^^^^^^^^^^^^^^^^^^^^^^^^^
  File "/home/data/freerad_api/.venv/lib/python3.13/site-packages/aiormq/abc.py", line 44, in __inner
    return await self.task
           ^^^^^^^^^^^^^^^
  File "/home/data/freerad_api/.venv/lib/python3.13/site-packages/aiormq/connection.py", line 457, in connect
    reader, writer = await asyncio.open_connection(
                     ^^^^^^^^^^^^^^^^^^^^^^^^^^^^^^
    ...<2 lines>...
    )
    ^
  File "/root/.local/share/uv/python/cpython-3.13.5-linux-x86_64-gnu/lib/python3.13/asyncio/streams.py", line 48, in open_connection
    transport, _ = await loop.create_connection(
                   ^^^^^^^^^^^^^^^^^^^^^^^^^^^^^
        lambda: protocol, host, port, **kwds)
        ^^^^^^^^^^^^^^^^^^^^^^^^^^^^^^^^^^^^^
  File "uvloop/loop.pyx", line 2050, in create_connection
ValueError: host and port was not specified and no sock specified
2025-08-04 20:02:53,526 - aio_pika.robust_connection - INFO - Connection to  closed. Reconnecting after 5 seconds.
2025-08-04 20:02:53,526 - aio_pika.robust_connection - ERROR - Reconnect attempt failed . Retrying after 5 seconds.
Traceback (most recent call last):
  File "/home/data/freerad_api/.venv/lib/python3.13/site-packages/aio_pika/robust_connection.py", line 135, in __connection_factory
    await Connection.connect(self, self.__connect_timeout)
  File "/home/data/freerad_api/.venv/lib/python3.13/site-packages/aio_pika/connection.py", line 125, in connect
    self.transport = await UnderlayConnection.connect(
                     ^^^^^^^^^^^^^^^^^^^^^^^^^^^^^^^^^
    ...<2 lines>...
    )
    ^
  File "/home/data/freerad_api/.venv/lib/python3.13/site-packages/aio_pika/abc.py", line 679, in connect
    connection = await cls.make_connection(
                 ^^^^^^^^^^^^^^^^^^^^^^^^^^
        url, timeout=timeout, **kwargs,
        ^^^^^^^^^^^^^^^^^^^^^^^^^^^^^^^
    )
    ^
  File "/home/data/freerad_api/.venv/lib/python3.13/site-packages/aio_pika/abc.py", line 667, in make_connection
    connection: aiormq.abc.AbstractConnection = await asyncio.wait_for(
                                                ^^^^^^^^^^^^^^^^^^^^^^^
        aiormq.connect(url, **kwargs), timeout=timeout,
        ^^^^^^^^^^^^^^^^^^^^^^^^^^^^^^^^^^^^^^^^^^^^^^^
    )
    ^
  File "/root/.local/share/uv/python/cpython-3.13.5-linux-x86_64-gnu/lib/python3.13/asyncio/tasks.py", line 507, in wait_for
    return await fut
           ^^^^^^^^^
  File "/home/data/freerad_api/.venv/lib/python3.13/site-packages/aiormq/connection.py", line 920, in connect
    await connection.connect(client_properties or {})
  File "/home/data/freerad_api/.venv/lib/python3.13/site-packages/aiormq/base.py", line 164, in wrap
    return await self.create_task(func(self, *args, **kwargs))
           ^^^^^^^^^^^^^^^^^^^^^^^^^^^^^^^^^^^^^^^^^^^^^^^^^^^
  File "/home/data/freerad_api/.venv/lib/python3.13/site-packages/aiormq/abc.py", line 44, in __inner
    return await self.task
           ^^^^^^^^^^^^^^^
  File "/home/data/freerad_api/.venv/lib/python3.13/site-packages/aiormq/connection.py", line 457, in connect
    reader, writer = await asyncio.open_connection(
                     ^^^^^^^^^^^^^^^^^^^^^^^^^^^^^^
    ...<2 lines>...
    )
    ^
  File "/root/.local/share/uv/python/cpython-3.13.5-linux-x86_64-gnu/lib/python3.13/asyncio/streams.py", line 48, in open_connection
    transport, _ = await loop.create_connection(
                   ^^^^^^^^^^^^^^^^^^^^^^^^^^^^^
        lambda: protocol, host, port, **kwds)
        ^^^^^^^^^^^^^^^^^^^^^^^^^^^^^^^^^^^^^
  File "uvloop/loop.pyx", line 2050, in create_connection
ValueError: host and port was not specified and no sock specified
2025-08-04 20:02:58,530 - aio_pika.robust_connection - INFO - Connection to  closed. Reconnecting after 5 seconds.
2025-08-04 20:02:58,530 - aio_pika.robust_connection - ERROR - Reconnect attempt failed . Retrying after 5 seconds.
Traceback (most recent call last):
  File "/home/data/freerad_api/.venv/lib/python3.13/site-packages/aio_pika/robust_connection.py", line 135, in __connection_factory
    await Connection.connect(self, self.__connect_timeout)
  File "/home/data/freerad_api/.venv/lib/python3.13/site-packages/aio_pika/connection.py", line 125, in connect
    self.transport = await UnderlayConnection.connect(
                     ^^^^^^^^^^^^^^^^^^^^^^^^^^^^^^^^^
    ...<2 lines>...
    )
    ^
  File "/home/data/freerad_api/.venv/lib/python3.13/site-packages/aio_pika/abc.py", line 679, in connect
    connection = await cls.make_connection(
                 ^^^^^^^^^^^^^^^^^^^^^^^^^^
        url, timeout=timeout, **kwargs,
        ^^^^^^^^^^^^^^^^^^^^^^^^^^^^^^^
    )
    ^
  File "/home/data/freerad_api/.venv/lib/python3.13/site-packages/aio_pika/abc.py", line 667, in make_connection
    connection: aiormq.abc.AbstractConnection = await asyncio.wait_for(
                                                ^^^^^^^^^^^^^^^^^^^^^^^
        aiormq.connect(url, **kwargs), timeout=timeout,
        ^^^^^^^^^^^^^^^^^^^^^^^^^^^^^^^^^^^^^^^^^^^^^^^
    )
    ^
  File "/root/.local/share/uv/python/cpython-3.13.5-linux-x86_64-gnu/lib/python3.13/asyncio/tasks.py", line 507, in wait_for
    return await fut
           ^^^^^^^^^
  File "/home/data/freerad_api/.venv/lib/python3.13/site-packages/aiormq/connection.py", line 920, in connect
    await connection.connect(client_properties or {})
  File "/home/data/freerad_api/.venv/lib/python3.13/site-packages/aiormq/base.py", line 164, in wrap
    return await self.create_task(func(self, *args, **kwargs))
           ^^^^^^^^^^^^^^^^^^^^^^^^^^^^^^^^^^^^^^^^^^^^^^^^^^^
  File "/home/data/freerad_api/.venv/lib/python3.13/site-packages/aiormq/abc.py", line 44, in __inner
    return await self.task
           ^^^^^^^^^^^^^^^
  File "/home/data/freerad_api/.venv/lib/python3.13/site-packages/aiormq/connection.py", line 457, in connect
    reader, writer = await asyncio.open_connection(
                     ^^^^^^^^^^^^^^^^^^^^^^^^^^^^^^
    ...<2 lines>...
    )
    ^
  File "/root/.local/share/uv/python/cpython-3.13.5-linux-x86_64-gnu/lib/python3.13/asyncio/streams.py", line 48, in open_connection
    transport, _ = await loop.create_connection(
                   ^^^^^^^^^^^^^^^^^^^^^^^^^^^^^
        lambda: protocol, host, port, **kwds)
        ^^^^^^^^^^^^^^^^^^^^^^^^^^^^^^^^^^^^^
  File "uvloop/loop.pyx", line 2050, in create_connection
ValueError: host and port was not specified and no sock specified
2025-08-04 20:03:03,534 - aio_pika.robust_connection - INFO - Connection to  closed. Reconnecting after 5 seconds.
2025-08-04 20:03:03,534 - aio_pika.robust_connection - ERROR - Reconnect attempt failed . Retrying after 5 seconds.
Traceback (most recent call last):
  File "/home/data/freerad_api/.venv/lib/python3.13/site-packages/aio_pika/robust_connection.py", line 135, in __connection_factory
    await Connection.connect(self, self.__connect_timeout)
  File "/home/data/freerad_api/.venv/lib/python3.13/site-packages/aio_pika/connection.py", line 125, in connect
    self.transport = await UnderlayConnection.connect(
                     ^^^^^^^^^^^^^^^^^^^^^^^^^^^^^^^^^
    ...<2 lines>...
    )
    ^
  File "/home/data/freerad_api/.venv/lib/python3.13/site-packages/aio_pika/abc.py", line 679, in connect
    connection = await cls.make_connection(
                 ^^^^^^^^^^^^^^^^^^^^^^^^^^
        url, timeout=timeout, **kwargs,
        ^^^^^^^^^^^^^^^^^^^^^^^^^^^^^^^
    )
    ^
  File "/home/data/freerad_api/.venv/lib/python3.13/site-packages/aio_pika/abc.py", line 667, in make_connection
    connection: aiormq.abc.AbstractConnection = await asyncio.wait_for(
                                                ^^^^^^^^^^^^^^^^^^^^^^^
        aiormq.connect(url, **kwargs), timeout=timeout,
        ^^^^^^^^^^^^^^^^^^^^^^^^^^^^^^^^^^^^^^^^^^^^^^^
    )
    ^
  File "/root/.local/share/uv/python/cpython-3.13.5-linux-x86_64-gnu/lib/python3.13/asyncio/tasks.py", line 507, in wait_for
    return await fut
           ^^^^^^^^^
  File "/home/data/freerad_api/.venv/lib/python3.13/site-packages/aiormq/connection.py", line 920, in connect
    await connection.connect(client_properties or {})
  File "/home/data/freerad_api/.venv/lib/python3.13/site-packages/aiormq/base.py", line 164, in wrap
    return await self.create_task(func(self, *args, **kwargs))
           ^^^^^^^^^^^^^^^^^^^^^^^^^^^^^^^^^^^^^^^^^^^^^^^^^^^
  File "/home/data/freerad_api/.venv/lib/python3.13/site-packages/aiormq/abc.py", line 44, in __inner
    return await self.task
           ^^^^^^^^^^^^^^^
  File "/home/data/freerad_api/.venv/lib/python3.13/site-packages/aiormq/connection.py", line 457, in connect
    reader, writer = await asyncio.open_connection(
                     ^^^^^^^^^^^^^^^^^^^^^^^^^^^^^^
    ...<2 lines>...
    )
    ^
  File "/root/.local/share/uv/python/cpython-3.13.5-linux-x86_64-gnu/lib/python3.13/asyncio/streams.py", line 48, in open_connection
    transport, _ = await loop.create_connection(
                   ^^^^^^^^^^^^^^^^^^^^^^^^^^^^^
        lambda: protocol, host, port, **kwds)
        ^^^^^^^^^^^^^^^^^^^^^^^^^^^^^^^^^^^^^
  File "uvloop/loop.pyx", line 2050, in create_connection
ValueError: host and port was not specified and no sock specified
2025-08-04 20:03:08,538 - aio_pika.robust_connection - INFO - Connection to  closed. Reconnecting after 5 seconds.
2025-08-04 20:03:08,538 - aio_pika.robust_connection - ERROR - Reconnect attempt failed . Retrying after 5 seconds.
Traceback (most recent call last):
  File "/home/data/freerad_api/.venv/lib/python3.13/site-packages/aio_pika/robust_connection.py", line 135, in __connection_factory
    await Connection.connect(self, self.__connect_timeout)
  File "/home/data/freerad_api/.venv/lib/python3.13/site-packages/aio_pika/connection.py", line 125, in connect
    self.transport = await UnderlayConnection.connect(
                     ^^^^^^^^^^^^^^^^^^^^^^^^^^^^^^^^^
    ...<2 lines>...
    )
    ^
  File "/home/data/freerad_api/.venv/lib/python3.13/site-packages/aio_pika/abc.py", line 679, in connect
    connection = await cls.make_connection(
                 ^^^^^^^^^^^^^^^^^^^^^^^^^^
        url, timeout=timeout, **kwargs,
        ^^^^^^^^^^^^^^^^^^^^^^^^^^^^^^^
    )
    ^
  File "/home/data/freerad_api/.venv/lib/python3.13/site-packages/aio_pika/abc.py", line 667, in make_connection
    connection: aiormq.abc.AbstractConnection = await asyncio.wait_for(
                                                ^^^^^^^^^^^^^^^^^^^^^^^
        aiormq.connect(url, **kwargs), timeout=timeout,
        ^^^^^^^^^^^^^^^^^^^^^^^^^^^^^^^^^^^^^^^^^^^^^^^
    )
    ^
  File "/root/.local/share/uv/python/cpython-3.13.5-linux-x86_64-gnu/lib/python3.13/asyncio/tasks.py", line 507, in wait_for
    return await fut
           ^^^^^^^^^
  File "/home/data/freerad_api/.venv/lib/python3.13/site-packages/aiormq/connection.py", line 920, in connect
    await connection.connect(client_properties or {})
  File "/home/data/freerad_api/.venv/lib/python3.13/site-packages/aiormq/base.py", line 164, in wrap
    return await self.create_task(func(self, *args, **kwargs))
           ^^^^^^^^^^^^^^^^^^^^^^^^^^^^^^^^^^^^^^^^^^^^^^^^^^^
  File "/home/data/freerad_api/.venv/lib/python3.13/site-packages/aiormq/abc.py", line 44, in __inner
    return await self.task
           ^^^^^^^^^^^^^^^
  File "/home/data/freerad_api/.venv/lib/python3.13/site-packages/aiormq/connection.py", line 457, in connect
    reader, writer = await asyncio.open_connection(
                     ^^^^^^^^^^^^^^^^^^^^^^^^^^^^^^
    ...<2 lines>...
    )
    ^
  File "/root/.local/share/uv/python/cpython-3.13.5-linux-x86_64-gnu/lib/python3.13/asyncio/streams.py", line 48, in open_connection
    transport, _ = await loop.create_connection(
                   ^^^^^^^^^^^^^^^^^^^^^^^^^^^^^
        lambda: protocol, host, port, **kwds)
        ^^^^^^^^^^^^^^^^^^^^^^^^^^^^^^^^^^^^^
  File "uvloop/loop.pyx", line 2050, in create_connection
ValueError: host and port was not specified and no sock specified
2025-08-04 20:03:13,542 - aio_pika.robust_connection - INFO - Connection to  closed. Reconnecting after 5 seconds.
2025-08-04 20:03:13,542 - aio_pika.robust_connection - ERROR - Reconnect attempt failed . Retrying after 5 seconds.
Traceback (most recent call last):
  File "/home/data/freerad_api/.venv/lib/python3.13/site-packages/aio_pika/robust_connection.py", line 135, in __connection_factory
    await Connection.connect(self, self.__connect_timeout)
  File "/home/data/freerad_api/.venv/lib/python3.13/site-packages/aio_pika/connection.py", line 125, in connect
    self.transport = await UnderlayConnection.connect(
                     ^^^^^^^^^^^^^^^^^^^^^^^^^^^^^^^^^
    ...<2 lines>...
    )
    ^
  File "/home/data/freerad_api/.venv/lib/python3.13/site-packages/aio_pika/abc.py", line 679, in connect
    connection = await cls.make_connection(
                 ^^^^^^^^^^^^^^^^^^^^^^^^^^
        url, timeout=timeout, **kwargs,
        ^^^^^^^^^^^^^^^^^^^^^^^^^^^^^^^
    )
    ^
  File "/home/data/freerad_api/.venv/lib/python3.13/site-packages/aio_pika/abc.py", line 667, in make_connection
    connection: aiormq.abc.AbstractConnection = await asyncio.wait_for(
                                                ^^^^^^^^^^^^^^^^^^^^^^^
        aiormq.connect(url, **kwargs), timeout=timeout,
        ^^^^^^^^^^^^^^^^^^^^^^^^^^^^^^^^^^^^^^^^^^^^^^^
    )
    ^
  File "/root/.local/share/uv/python/cpython-3.13.5-linux-x86_64-gnu/lib/python3.13/asyncio/tasks.py", line 507, in wait_for
    return await fut
           ^^^^^^^^^
  File "/home/data/freerad_api/.venv/lib/python3.13/site-packages/aiormq/connection.py", line 920, in connect
    await connection.connect(client_properties or {})
  File "/home/data/freerad_api/.venv/lib/python3.13/site-packages/aiormq/base.py", line 164, in wrap
    return await self.create_task(func(self, *args, **kwargs))
           ^^^^^^^^^^^^^^^^^^^^^^^^^^^^^^^^^^^^^^^^^^^^^^^^^^^
  File "/home/data/freerad_api/.venv/lib/python3.13/site-packages/aiormq/abc.py", line 44, in __inner
    return await self.task
           ^^^^^^^^^^^^^^^
  File "/home/data/freerad_api/.venv/lib/python3.13/site-packages/aiormq/connection.py", line 457, in connect
    reader, writer = await asyncio.open_connection(
                     ^^^^^^^^^^^^^^^^^^^^^^^^^^^^^^
    ...<2 lines>...
    )
    ^
  File "/root/.local/share/uv/python/cpython-3.13.5-linux-x86_64-gnu/lib/python3.13/asyncio/streams.py", line 48, in open_connection
    transport, _ = await loop.create_connection(
                   ^^^^^^^^^^^^^^^^^^^^^^^^^^^^^
        lambda: protocol, host, port, **kwds)
        ^^^^^^^^^^^^^^^^^^^^^^^^^^^^^^^^^^^^^
  File "uvloop/loop.pyx", line 2050, in create_connection
ValueError: host and port was not specified and no sock specified
2025-08-04 20:03:27,204 - main - INFO - Starting Radius Core service...
2025-08-04 20:03:27,204 - redis_client - ERROR - Failed to connect to Redis: Redis URL must specify one of the following schemes (redis://, rediss://, unix://)
2025-08-04 20:03:27,204 - redis_client - ERROR - Redis health check failed: Redis URL must specify one of the following schemes (redis://, rediss://, unix://)
2025-08-04 20:03:27,204 - main - ERROR - Redis health check failed
2025-08-04 20:03:27,205 - aio_pika.robust_connection - INFO - Connection to  closed. Reconnecting after 5 seconds.
2025-08-04 20:03:27,205 - aio_pika.robust_connection - ERROR - Reconnect attempt failed . Retrying after 5 seconds.
Traceback (most recent call last):
  File "/home/data/freerad_api/.venv/lib/python3.13/site-packages/aio_pika/robust_connection.py", line 135, in __connection_factory
    await Connection.connect(self, self.__connect_timeout)
  File "/home/data/freerad_api/.venv/lib/python3.13/site-packages/aio_pika/connection.py", line 125, in connect
    self.transport = await UnderlayConnection.connect(
                     ^^^^^^^^^^^^^^^^^^^^^^^^^^^^^^^^^
    ...<2 lines>...
    )
    ^
  File "/home/data/freerad_api/.venv/lib/python3.13/site-packages/aio_pika/abc.py", line 679, in connect
    connection = await cls.make_connection(
                 ^^^^^^^^^^^^^^^^^^^^^^^^^^
        url, timeout=timeout, **kwargs,
        ^^^^^^^^^^^^^^^^^^^^^^^^^^^^^^^
    )
    ^
  File "/home/data/freerad_api/.venv/lib/python3.13/site-packages/aio_pika/abc.py", line 667, in make_connection
    connection: aiormq.abc.AbstractConnection = await asyncio.wait_for(
                                                ^^^^^^^^^^^^^^^^^^^^^^^
        aiormq.connect(url, **kwargs), timeout=timeout,
        ^^^^^^^^^^^^^^^^^^^^^^^^^^^^^^^^^^^^^^^^^^^^^^^
    )
    ^
  File "/root/.local/share/uv/python/cpython-3.13.5-linux-x86_64-gnu/lib/python3.13/asyncio/tasks.py", line 507, in wait_for
    return await fut
           ^^^^^^^^^
  File "/home/data/freerad_api/.venv/lib/python3.13/site-packages/aiormq/connection.py", line 920, in connect
    await connection.connect(client_properties or {})
  File "/home/data/freerad_api/.venv/lib/python3.13/site-packages/aiormq/base.py", line 164, in wrap
    return await self.create_task(func(self, *args, **kwargs))
           ^^^^^^^^^^^^^^^^^^^^^^^^^^^^^^^^^^^^^^^^^^^^^^^^^^^
  File "/home/data/freerad_api/.venv/lib/python3.13/site-packages/aiormq/abc.py", line 44, in __inner
    return await self.task
           ^^^^^^^^^^^^^^^
  File "/home/data/freerad_api/.venv/lib/python3.13/site-packages/aiormq/connection.py", line 457, in connect
    reader, writer = await asyncio.open_connection(
                     ^^^^^^^^^^^^^^^^^^^^^^^^^^^^^^
    ...<2 lines>...
    )
    ^
  File "/root/.local/share/uv/python/cpython-3.13.5-linux-x86_64-gnu/lib/python3.13/asyncio/streams.py", line 48, in open_connection
    transport, _ = await loop.create_connection(
                   ^^^^^^^^^^^^^^^^^^^^^^^^^^^^^
        lambda: protocol, host, port, **kwds)
        ^^^^^^^^^^^^^^^^^^^^^^^^^^^^^^^^^^^^^
  File "uvloop/loop.pyx", line 2050, in create_connection
ValueError: host and port was not specified and no sock specified
2025-08-04 20:03:32,210 - aio_pika.robust_connection - INFO - Connection to  closed. Reconnecting after 5 seconds.
2025-08-04 20:03:32,210 - aio_pika.robust_connection - ERROR - Reconnect attempt failed . Retrying after 5 seconds.
Traceback (most recent call last):
  File "/home/data/freerad_api/.venv/lib/python3.13/site-packages/aio_pika/robust_connection.py", line 135, in __connection_factory
    await Connection.connect(self, self.__connect_timeout)
  File "/home/data/freerad_api/.venv/lib/python3.13/site-packages/aio_pika/connection.py", line 125, in connect
    self.transport = await UnderlayConnection.connect(
                     ^^^^^^^^^^^^^^^^^^^^^^^^^^^^^^^^^
    ...<2 lines>...
    )
    ^
  File "/home/data/freerad_api/.venv/lib/python3.13/site-packages/aio_pika/abc.py", line 679, in connect
    connection = await cls.make_connection(
                 ^^^^^^^^^^^^^^^^^^^^^^^^^^
        url, timeout=timeout, **kwargs,
        ^^^^^^^^^^^^^^^^^^^^^^^^^^^^^^^
    )
    ^
  File "/home/data/freerad_api/.venv/lib/python3.13/site-packages/aio_pika/abc.py", line 667, in make_connection
    connection: aiormq.abc.AbstractConnection = await asyncio.wait_for(
                                                ^^^^^^^^^^^^^^^^^^^^^^^
        aiormq.connect(url, **kwargs), timeout=timeout,
        ^^^^^^^^^^^^^^^^^^^^^^^^^^^^^^^^^^^^^^^^^^^^^^^
    )
    ^
  File "/root/.local/share/uv/python/cpython-3.13.5-linux-x86_64-gnu/lib/python3.13/asyncio/tasks.py", line 507, in wait_for
    return await fut
           ^^^^^^^^^
  File "/home/data/freerad_api/.venv/lib/python3.13/site-packages/aiormq/connection.py", line 920, in connect
    await connection.connect(client_properties or {})
  File "/home/data/freerad_api/.venv/lib/python3.13/site-packages/aiormq/base.py", line 164, in wrap
    return await self.create_task(func(self, *args, **kwargs))
           ^^^^^^^^^^^^^^^^^^^^^^^^^^^^^^^^^^^^^^^^^^^^^^^^^^^
  File "/home/data/freerad_api/.venv/lib/python3.13/site-packages/aiormq/abc.py", line 44, in __inner
    return await self.task
           ^^^^^^^^^^^^^^^
  File "/home/data/freerad_api/.venv/lib/python3.13/site-packages/aiormq/connection.py", line 457, in connect
    reader, writer = await asyncio.open_connection(
                     ^^^^^^^^^^^^^^^^^^^^^^^^^^^^^^
    ...<2 lines>...
    )
    ^
  File "/root/.local/share/uv/python/cpython-3.13.5-linux-x86_64-gnu/lib/python3.13/asyncio/streams.py", line 48, in open_connection
    transport, _ = await loop.create_connection(
                   ^^^^^^^^^^^^^^^^^^^^^^^^^^^^^
        lambda: protocol, host, port, **kwds)
        ^^^^^^^^^^^^^^^^^^^^^^^^^^^^^^^^^^^^^
  File "uvloop/loop.pyx", line 2050, in create_connection
ValueError: host and port was not specified and no sock specified
2025-08-04 20:03:37,214 - aio_pika.robust_connection - INFO - Connection to  closed. Reconnecting after 5 seconds.
2025-08-04 20:03:37,214 - aio_pika.robust_connection - ERROR - Reconnect attempt failed . Retrying after 5 seconds.
Traceback (most recent call last):
  File "/home/data/freerad_api/.venv/lib/python3.13/site-packages/aio_pika/robust_connection.py", line 135, in __connection_factory
    await Connection.connect(self, self.__connect_timeout)
  File "/home/data/freerad_api/.venv/lib/python3.13/site-packages/aio_pika/connection.py", line 125, in connect
    self.transport = await UnderlayConnection.connect(
                     ^^^^^^^^^^^^^^^^^^^^^^^^^^^^^^^^^
    ...<2 lines>...
    )
    ^
  File "/home/data/freerad_api/.venv/lib/python3.13/site-packages/aio_pika/abc.py", line 679, in connect
    connection = await cls.make_connection(
                 ^^^^^^^^^^^^^^^^^^^^^^^^^^
        url, timeout=timeout, **kwargs,
        ^^^^^^^^^^^^^^^^^^^^^^^^^^^^^^^
    )
    ^
  File "/home/data/freerad_api/.venv/lib/python3.13/site-packages/aio_pika/abc.py", line 667, in make_connection
    connection: aiormq.abc.AbstractConnection = await asyncio.wait_for(
                                                ^^^^^^^^^^^^^^^^^^^^^^^
        aiormq.connect(url, **kwargs), timeout=timeout,
        ^^^^^^^^^^^^^^^^^^^^^^^^^^^^^^^^^^^^^^^^^^^^^^^
    )
    ^
  File "/root/.local/share/uv/python/cpython-3.13.5-linux-x86_64-gnu/lib/python3.13/asyncio/tasks.py", line 507, in wait_for
    return await fut
           ^^^^^^^^^
  File "/home/data/freerad_api/.venv/lib/python3.13/site-packages/aiormq/connection.py", line 920, in connect
    await connection.connect(client_properties or {})
  File "/home/data/freerad_api/.venv/lib/python3.13/site-packages/aiormq/base.py", line 164, in wrap
    return await self.create_task(func(self, *args, **kwargs))
           ^^^^^^^^^^^^^^^^^^^^^^^^^^^^^^^^^^^^^^^^^^^^^^^^^^^
  File "/home/data/freerad_api/.venv/lib/python3.13/site-packages/aiormq/abc.py", line 44, in __inner
    return await self.task
           ^^^^^^^^^^^^^^^
  File "/home/data/freerad_api/.venv/lib/python3.13/site-packages/aiormq/connection.py", line 457, in connect
    reader, writer = await asyncio.open_connection(
                     ^^^^^^^^^^^^^^^^^^^^^^^^^^^^^^
    ...<2 lines>...
    )
    ^
  File "/root/.local/share/uv/python/cpython-3.13.5-linux-x86_64-gnu/lib/python3.13/asyncio/streams.py", line 48, in open_connection
    transport, _ = await loop.create_connection(
                   ^^^^^^^^^^^^^^^^^^^^^^^^^^^^^
        lambda: protocol, host, port, **kwds)
        ^^^^^^^^^^^^^^^^^^^^^^^^^^^^^^^^^^^^^
  File "uvloop/loop.pyx", line 2050, in create_connection
ValueError: host and port was not specified and no sock specified
2025-08-04 20:03:42,218 - aio_pika.robust_connection - INFO - Connection to  closed. Reconnecting after 5 seconds.
2025-08-04 20:03:42,218 - aio_pika.robust_connection - ERROR - Reconnect attempt failed . Retrying after 5 seconds.
Traceback (most recent call last):
  File "/home/data/freerad_api/.venv/lib/python3.13/site-packages/aio_pika/robust_connection.py", line 135, in __connection_factory
    await Connection.connect(self, self.__connect_timeout)
  File "/home/data/freerad_api/.venv/lib/python3.13/site-packages/aio_pika/connection.py", line 125, in connect
    self.transport = await UnderlayConnection.connect(
                     ^^^^^^^^^^^^^^^^^^^^^^^^^^^^^^^^^
    ...<2 lines>...
    )
    ^
  File "/home/data/freerad_api/.venv/lib/python3.13/site-packages/aio_pika/abc.py", line 679, in connect
    connection = await cls.make_connection(
                 ^^^^^^^^^^^^^^^^^^^^^^^^^^
        url, timeout=timeout, **kwargs,
        ^^^^^^^^^^^^^^^^^^^^^^^^^^^^^^^
    )
    ^
  File "/home/data/freerad_api/.venv/lib/python3.13/site-packages/aio_pika/abc.py", line 667, in make_connection
    connection: aiormq.abc.AbstractConnection = await asyncio.wait_for(
                                                ^^^^^^^^^^^^^^^^^^^^^^^
        aiormq.connect(url, **kwargs), timeout=timeout,
        ^^^^^^^^^^^^^^^^^^^^^^^^^^^^^^^^^^^^^^^^^^^^^^^
    )
    ^
  File "/root/.local/share/uv/python/cpython-3.13.5-linux-x86_64-gnu/lib/python3.13/asyncio/tasks.py", line 507, in wait_for
    return await fut
           ^^^^^^^^^
  File "/home/data/freerad_api/.venv/lib/python3.13/site-packages/aiormq/connection.py", line 920, in connect
    await connection.connect(client_properties or {})
  File "/home/data/freerad_api/.venv/lib/python3.13/site-packages/aiormq/base.py", line 164, in wrap
    return await self.create_task(func(self, *args, **kwargs))
           ^^^^^^^^^^^^^^^^^^^^^^^^^^^^^^^^^^^^^^^^^^^^^^^^^^^
  File "/home/data/freerad_api/.venv/lib/python3.13/site-packages/aiormq/abc.py", line 44, in __inner
    return await self.task
           ^^^^^^^^^^^^^^^
  File "/home/data/freerad_api/.venv/lib/python3.13/site-packages/aiormq/connection.py", line 457, in connect
    reader, writer = await asyncio.open_connection(
                     ^^^^^^^^^^^^^^^^^^^^^^^^^^^^^^
    ...<2 lines>...
    )
    ^
  File "/root/.local/share/uv/python/cpython-3.13.5-linux-x86_64-gnu/lib/python3.13/asyncio/streams.py", line 48, in open_connection
    transport, _ = await loop.create_connection(
                   ^^^^^^^^^^^^^^^^^^^^^^^^^^^^^
        lambda: protocol, host, port, **kwds)
        ^^^^^^^^^^^^^^^^^^^^^^^^^^^^^^^^^^^^^
  File "uvloop/loop.pyx", line 2050, in create_connection
ValueError: host and port was not specified and no sock specified
2025-08-04 20:03:47,222 - aio_pika.robust_connection - INFO - Connection to  closed. Reconnecting after 5 seconds.
2025-08-04 20:03:47,222 - aio_pika.robust_connection - ERROR - Reconnect attempt failed . Retrying after 5 seconds.
Traceback (most recent call last):
  File "/home/data/freerad_api/.venv/lib/python3.13/site-packages/aio_pika/robust_connection.py", line 135, in __connection_factory
    await Connection.connect(self, self.__connect_timeout)
  File "/home/data/freerad_api/.venv/lib/python3.13/site-packages/aio_pika/connection.py", line 125, in connect
    self.transport = await UnderlayConnection.connect(
                     ^^^^^^^^^^^^^^^^^^^^^^^^^^^^^^^^^
    ...<2 lines>...
    )
    ^
  File "/home/data/freerad_api/.venv/lib/python3.13/site-packages/aio_pika/abc.py", line 679, in connect
    connection = await cls.make_connection(
                 ^^^^^^^^^^^^^^^^^^^^^^^^^^
        url, timeout=timeout, **kwargs,
        ^^^^^^^^^^^^^^^^^^^^^^^^^^^^^^^
    )
    ^
  File "/home/data/freerad_api/.venv/lib/python3.13/site-packages/aio_pika/abc.py", line 667, in make_connection
    connection: aiormq.abc.AbstractConnection = await asyncio.wait_for(
                                                ^^^^^^^^^^^^^^^^^^^^^^^
        aiormq.connect(url, **kwargs), timeout=timeout,
        ^^^^^^^^^^^^^^^^^^^^^^^^^^^^^^^^^^^^^^^^^^^^^^^
    )
    ^
  File "/root/.local/share/uv/python/cpython-3.13.5-linux-x86_64-gnu/lib/python3.13/asyncio/tasks.py", line 507, in wait_for
    return await fut
           ^^^^^^^^^
  File "/home/data/freerad_api/.venv/lib/python3.13/site-packages/aiormq/connection.py", line 920, in connect
    await connection.connect(client_properties or {})
  File "/home/data/freerad_api/.venv/lib/python3.13/site-packages/aiormq/base.py", line 164, in wrap
    return await self.create_task(func(self, *args, **kwargs))
           ^^^^^^^^^^^^^^^^^^^^^^^^^^^^^^^^^^^^^^^^^^^^^^^^^^^
  File "/home/data/freerad_api/.venv/lib/python3.13/site-packages/aiormq/abc.py", line 44, in __inner
    return await self.task
           ^^^^^^^^^^^^^^^
  File "/home/data/freerad_api/.venv/lib/python3.13/site-packages/aiormq/connection.py", line 457, in connect
    reader, writer = await asyncio.open_connection(
                     ^^^^^^^^^^^^^^^^^^^^^^^^^^^^^^
    ...<2 lines>...
    )
    ^
  File "/root/.local/share/uv/python/cpython-3.13.5-linux-x86_64-gnu/lib/python3.13/asyncio/streams.py", line 48, in open_connection
    transport, _ = await loop.create_connection(
                   ^^^^^^^^^^^^^^^^^^^^^^^^^^^^^
        lambda: protocol, host, port, **kwds)
        ^^^^^^^^^^^^^^^^^^^^^^^^^^^^^^^^^^^^^
  File "uvloop/loop.pyx", line 2050, in create_connection
ValueError: host and port was not specified and no sock specified
2025-08-04 20:03:52,226 - aio_pika.robust_connection - INFO - Connection to  closed. Reconnecting after 5 seconds.
2025-08-04 20:03:52,226 - aio_pika.robust_connection - ERROR - Reconnect attempt failed . Retrying after 5 seconds.
Traceback (most recent call last):
  File "/home/data/freerad_api/.venv/lib/python3.13/site-packages/aio_pika/robust_connection.py", line 135, in __connection_factory
    await Connection.connect(self, self.__connect_timeout)
  File "/home/data/freerad_api/.venv/lib/python3.13/site-packages/aio_pika/connection.py", line 125, in connect
    self.transport = await UnderlayConnection.connect(
                     ^^^^^^^^^^^^^^^^^^^^^^^^^^^^^^^^^
    ...<2 lines>...
    )
    ^
  File "/home/data/freerad_api/.venv/lib/python3.13/site-packages/aio_pika/abc.py", line 679, in connect
    connection = await cls.make_connection(
                 ^^^^^^^^^^^^^^^^^^^^^^^^^^
        url, timeout=timeout, **kwargs,
        ^^^^^^^^^^^^^^^^^^^^^^^^^^^^^^^
    )
    ^
  File "/home/data/freerad_api/.venv/lib/python3.13/site-packages/aio_pika/abc.py", line 667, in make_connection
    connection: aiormq.abc.AbstractConnection = await asyncio.wait_for(
                                                ^^^^^^^^^^^^^^^^^^^^^^^
        aiormq.connect(url, **kwargs), timeout=timeout,
        ^^^^^^^^^^^^^^^^^^^^^^^^^^^^^^^^^^^^^^^^^^^^^^^
    )
    ^
  File "/root/.local/share/uv/python/cpython-3.13.5-linux-x86_64-gnu/lib/python3.13/asyncio/tasks.py", line 507, in wait_for
    return await fut
           ^^^^^^^^^
  File "/home/data/freerad_api/.venv/lib/python3.13/site-packages/aiormq/connection.py", line 920, in connect
    await connection.connect(client_properties or {})
  File "/home/data/freerad_api/.venv/lib/python3.13/site-packages/aiormq/base.py", line 164, in wrap
    return await self.create_task(func(self, *args, **kwargs))
           ^^^^^^^^^^^^^^^^^^^^^^^^^^^^^^^^^^^^^^^^^^^^^^^^^^^
  File "/home/data/freerad_api/.venv/lib/python3.13/site-packages/aiormq/abc.py", line 44, in __inner
    return await self.task
           ^^^^^^^^^^^^^^^
  File "/home/data/freerad_api/.venv/lib/python3.13/site-packages/aiormq/connection.py", line 457, in connect
    reader, writer = await asyncio.open_connection(
                     ^^^^^^^^^^^^^^^^^^^^^^^^^^^^^^
    ...<2 lines>...
    )
    ^
  File "/root/.local/share/uv/python/cpython-3.13.5-linux-x86_64-gnu/lib/python3.13/asyncio/streams.py", line 48, in open_connection
    transport, _ = await loop.create_connection(
                   ^^^^^^^^^^^^^^^^^^^^^^^^^^^^^
        lambda: protocol, host, port, **kwds)
        ^^^^^^^^^^^^^^^^^^^^^^^^^^^^^^^^^^^^^
  File "uvloop/loop.pyx", line 2050, in create_connection
ValueError: host and port was not specified and no sock specified
2025-08-04 20:03:57,230 - aio_pika.robust_connection - INFO - Connection to  closed. Reconnecting after 5 seconds.
2025-08-04 20:03:57,230 - aio_pika.robust_connection - ERROR - Reconnect attempt failed . Retrying after 5 seconds.
Traceback (most recent call last):
  File "/home/data/freerad_api/.venv/lib/python3.13/site-packages/aio_pika/robust_connection.py", line 135, in __connection_factory
    await Connection.connect(self, self.__connect_timeout)
  File "/home/data/freerad_api/.venv/lib/python3.13/site-packages/aio_pika/connection.py", line 125, in connect
    self.transport = await UnderlayConnection.connect(
                     ^^^^^^^^^^^^^^^^^^^^^^^^^^^^^^^^^
    ...<2 lines>...
    )
    ^
  File "/home/data/freerad_api/.venv/lib/python3.13/site-packages/aio_pika/abc.py", line 679, in connect
    connection = await cls.make_connection(
                 ^^^^^^^^^^^^^^^^^^^^^^^^^^
        url, timeout=timeout, **kwargs,
        ^^^^^^^^^^^^^^^^^^^^^^^^^^^^^^^
    )
    ^
  File "/home/data/freerad_api/.venv/lib/python3.13/site-packages/aio_pika/abc.py", line 667, in make_connection
    connection: aiormq.abc.AbstractConnection = await asyncio.wait_for(
                                                ^^^^^^^^^^^^^^^^^^^^^^^
        aiormq.connect(url, **kwargs), timeout=timeout,
        ^^^^^^^^^^^^^^^^^^^^^^^^^^^^^^^^^^^^^^^^^^^^^^^
    )
    ^
  File "/root/.local/share/uv/python/cpython-3.13.5-linux-x86_64-gnu/lib/python3.13/asyncio/tasks.py", line 507, in wait_for
    return await fut
           ^^^^^^^^^
  File "/home/data/freerad_api/.venv/lib/python3.13/site-packages/aiormq/connection.py", line 920, in connect
    await connection.connect(client_properties or {})
  File "/home/data/freerad_api/.venv/lib/python3.13/site-packages/aiormq/base.py", line 164, in wrap
    return await self.create_task(func(self, *args, **kwargs))
           ^^^^^^^^^^^^^^^^^^^^^^^^^^^^^^^^^^^^^^^^^^^^^^^^^^^
  File "/home/data/freerad_api/.venv/lib/python3.13/site-packages/aiormq/abc.py", line 44, in __inner
    return await self.task
           ^^^^^^^^^^^^^^^
  File "/home/data/freerad_api/.venv/lib/python3.13/site-packages/aiormq/connection.py", line 457, in connect
    reader, writer = await asyncio.open_connection(
                     ^^^^^^^^^^^^^^^^^^^^^^^^^^^^^^
    ...<2 lines>...
    )
    ^
  File "/root/.local/share/uv/python/cpython-3.13.5-linux-x86_64-gnu/lib/python3.13/asyncio/streams.py", line 48, in open_connection
    transport, _ = await loop.create_connection(
                   ^^^^^^^^^^^^^^^^^^^^^^^^^^^^^
        lambda: protocol, host, port, **kwds)
        ^^^^^^^^^^^^^^^^^^^^^^^^^^^^^^^^^^^^^
  File "uvloop/loop.pyx", line 2050, in create_connection
ValueError: host and port was not specified and no sock specified
2025-08-04 20:04:02,234 - aio_pika.robust_connection - INFO - Connection to  closed. Reconnecting after 5 seconds.
2025-08-04 20:04:02,234 - aio_pika.robust_connection - ERROR - Reconnect attempt failed . Retrying after 5 seconds.
Traceback (most recent call last):
  File "/home/data/freerad_api/.venv/lib/python3.13/site-packages/aio_pika/robust_connection.py", line 135, in __connection_factory
    await Connection.connect(self, self.__connect_timeout)
  File "/home/data/freerad_api/.venv/lib/python3.13/site-packages/aio_pika/connection.py", line 125, in connect
    self.transport = await UnderlayConnection.connect(
                     ^^^^^^^^^^^^^^^^^^^^^^^^^^^^^^^^^
    ...<2 lines>...
    )
    ^
  File "/home/data/freerad_api/.venv/lib/python3.13/site-packages/aio_pika/abc.py", line 679, in connect
    connection = await cls.make_connection(
                 ^^^^^^^^^^^^^^^^^^^^^^^^^^
        url, timeout=timeout, **kwargs,
        ^^^^^^^^^^^^^^^^^^^^^^^^^^^^^^^
    )
    ^
  File "/home/data/freerad_api/.venv/lib/python3.13/site-packages/aio_pika/abc.py", line 667, in make_connection
    connection: aiormq.abc.AbstractConnection = await asyncio.wait_for(
                                                ^^^^^^^^^^^^^^^^^^^^^^^
        aiormq.connect(url, **kwargs), timeout=timeout,
        ^^^^^^^^^^^^^^^^^^^^^^^^^^^^^^^^^^^^^^^^^^^^^^^
    )
    ^
  File "/root/.local/share/uv/python/cpython-3.13.5-linux-x86_64-gnu/lib/python3.13/asyncio/tasks.py", line 507, in wait_for
    return await fut
           ^^^^^^^^^
  File "/home/data/freerad_api/.venv/lib/python3.13/site-packages/aiormq/connection.py", line 920, in connect
    await connection.connect(client_properties or {})
  File "/home/data/freerad_api/.venv/lib/python3.13/site-packages/aiormq/base.py", line 164, in wrap
    return await self.create_task(func(self, *args, **kwargs))
           ^^^^^^^^^^^^^^^^^^^^^^^^^^^^^^^^^^^^^^^^^^^^^^^^^^^
  File "/home/data/freerad_api/.venv/lib/python3.13/site-packages/aiormq/abc.py", line 44, in __inner
    return await self.task
           ^^^^^^^^^^^^^^^
  File "/home/data/freerad_api/.venv/lib/python3.13/site-packages/aiormq/connection.py", line 457, in connect
    reader, writer = await asyncio.open_connection(
                     ^^^^^^^^^^^^^^^^^^^^^^^^^^^^^^
    ...<2 lines>...
    )
    ^
  File "/root/.local/share/uv/python/cpython-3.13.5-linux-x86_64-gnu/lib/python3.13/asyncio/streams.py", line 48, in open_connection
    transport, _ = await loop.create_connection(
                   ^^^^^^^^^^^^^^^^^^^^^^^^^^^^^
        lambda: protocol, host, port, **kwds)
        ^^^^^^^^^^^^^^^^^^^^^^^^^^^^^^^^^^^^^
  File "uvloop/loop.pyx", line 2050, in create_connection
ValueError: host and port was not specified and no sock specified
2025-08-04 20:04:48,594 - main - INFO - Starting Radius Core service...
2025-08-04 20:04:48,594 - redis_client - ERROR - Failed to connect to Redis: Redis URL must specify one of the following schemes (redis://, rediss://, unix://)
2025-08-04 20:04:48,594 - redis_client - ERROR - Redis health check failed: Redis URL must specify one of the following schemes (redis://, rediss://, unix://)
2025-08-04 20:04:48,594 - main - ERROR - Redis health check failed
2025-08-04 20:04:48,594 - aio_pika.robust_connection - INFO - Connection to  closed. Reconnecting after 5 seconds.
2025-08-04 20:04:48,594 - aio_pika.robust_connection - ERROR - Reconnect attempt failed . Retrying after 5 seconds.
Traceback (most recent call last):
  File "/home/data/freerad_api/.venv/lib/python3.13/site-packages/aio_pika/robust_connection.py", line 135, in __connection_factory
    await Connection.connect(self, self.__connect_timeout)
  File "/home/data/freerad_api/.venv/lib/python3.13/site-packages/aio_pika/connection.py", line 125, in connect
    self.transport = await UnderlayConnection.connect(
                     ^^^^^^^^^^^^^^^^^^^^^^^^^^^^^^^^^
    ...<2 lines>...
    )
    ^
  File "/home/data/freerad_api/.venv/lib/python3.13/site-packages/aio_pika/abc.py", line 679, in connect
    connection = await cls.make_connection(
                 ^^^^^^^^^^^^^^^^^^^^^^^^^^
        url, timeout=timeout, **kwargs,
        ^^^^^^^^^^^^^^^^^^^^^^^^^^^^^^^
    )
    ^
  File "/home/data/freerad_api/.venv/lib/python3.13/site-packages/aio_pika/abc.py", line 667, in make_connection
    connection: aiormq.abc.AbstractConnection = await asyncio.wait_for(
                                                ^^^^^^^^^^^^^^^^^^^^^^^
        aiormq.connect(url, **kwargs), timeout=timeout,
        ^^^^^^^^^^^^^^^^^^^^^^^^^^^^^^^^^^^^^^^^^^^^^^^
    )
    ^
  File "/root/.local/share/uv/python/cpython-3.13.5-linux-x86_64-gnu/lib/python3.13/asyncio/tasks.py", line 507, in wait_for
    return await fut
           ^^^^^^^^^
  File "/home/data/freerad_api/.venv/lib/python3.13/site-packages/aiormq/connection.py", line 920, in connect
    await connection.connect(client_properties or {})
  File "/home/data/freerad_api/.venv/lib/python3.13/site-packages/aiormq/base.py", line 164, in wrap
    return await self.create_task(func(self, *args, **kwargs))
           ^^^^^^^^^^^^^^^^^^^^^^^^^^^^^^^^^^^^^^^^^^^^^^^^^^^
  File "/home/data/freerad_api/.venv/lib/python3.13/site-packages/aiormq/abc.py", line 44, in __inner
    return await self.task
           ^^^^^^^^^^^^^^^
  File "/home/data/freerad_api/.venv/lib/python3.13/site-packages/aiormq/connection.py", line 457, in connect
    reader, writer = await asyncio.open_connection(
                     ^^^^^^^^^^^^^^^^^^^^^^^^^^^^^^
    ...<2 lines>...
    )
    ^
  File "/root/.local/share/uv/python/cpython-3.13.5-linux-x86_64-gnu/lib/python3.13/asyncio/streams.py", line 48, in open_connection
    transport, _ = await loop.create_connection(
                   ^^^^^^^^^^^^^^^^^^^^^^^^^^^^^
        lambda: protocol, host, port, **kwds)
        ^^^^^^^^^^^^^^^^^^^^^^^^^^^^^^^^^^^^^
  File "uvloop/loop.pyx", line 2050, in create_connection
ValueError: host and port was not specified and no sock specified
2025-08-04 20:04:53,598 - aio_pika.robust_connection - INFO - Connection to  closed. Reconnecting after 5 seconds.
2025-08-04 20:04:53,598 - aio_pika.robust_connection - ERROR - Reconnect attempt failed . Retrying after 5 seconds.
Traceback (most recent call last):
  File "/home/data/freerad_api/.venv/lib/python3.13/site-packages/aio_pika/robust_connection.py", line 135, in __connection_factory
    await Connection.connect(self, self.__connect_timeout)
  File "/home/data/freerad_api/.venv/lib/python3.13/site-packages/aio_pika/connection.py", line 125, in connect
    self.transport = await UnderlayConnection.connect(
                     ^^^^^^^^^^^^^^^^^^^^^^^^^^^^^^^^^
    ...<2 lines>...
    )
    ^
  File "/home/data/freerad_api/.venv/lib/python3.13/site-packages/aio_pika/abc.py", line 679, in connect
    connection = await cls.make_connection(
                 ^^^^^^^^^^^^^^^^^^^^^^^^^^
        url, timeout=timeout, **kwargs,
        ^^^^^^^^^^^^^^^^^^^^^^^^^^^^^^^
    )
    ^
  File "/home/data/freerad_api/.venv/lib/python3.13/site-packages/aio_pika/abc.py", line 667, in make_connection
    connection: aiormq.abc.AbstractConnection = await asyncio.wait_for(
                                                ^^^^^^^^^^^^^^^^^^^^^^^
        aiormq.connect(url, **kwargs), timeout=timeout,
        ^^^^^^^^^^^^^^^^^^^^^^^^^^^^^^^^^^^^^^^^^^^^^^^
    )
    ^
  File "/root/.local/share/uv/python/cpython-3.13.5-linux-x86_64-gnu/lib/python3.13/asyncio/tasks.py", line 507, in wait_for
    return await fut
           ^^^^^^^^^
  File "/home/data/freerad_api/.venv/lib/python3.13/site-packages/aiormq/connection.py", line 920, in connect
    await connection.connect(client_properties or {})
  File "/home/data/freerad_api/.venv/lib/python3.13/site-packages/aiormq/base.py", line 164, in wrap
    return await self.create_task(func(self, *args, **kwargs))
           ^^^^^^^^^^^^^^^^^^^^^^^^^^^^^^^^^^^^^^^^^^^^^^^^^^^
  File "/home/data/freerad_api/.venv/lib/python3.13/site-packages/aiormq/abc.py", line 44, in __inner
    return await self.task
           ^^^^^^^^^^^^^^^
  File "/home/data/freerad_api/.venv/lib/python3.13/site-packages/aiormq/connection.py", line 457, in connect
    reader, writer = await asyncio.open_connection(
                     ^^^^^^^^^^^^^^^^^^^^^^^^^^^^^^
    ...<2 lines>...
    )
    ^
  File "/root/.local/share/uv/python/cpython-3.13.5-linux-x86_64-gnu/lib/python3.13/asyncio/streams.py", line 48, in open_connection
    transport, _ = await loop.create_connection(
                   ^^^^^^^^^^^^^^^^^^^^^^^^^^^^^
        lambda: protocol, host, port, **kwds)
        ^^^^^^^^^^^^^^^^^^^^^^^^^^^^^^^^^^^^^
  File "uvloop/loop.pyx", line 2050, in create_connection
ValueError: host and port was not specified and no sock specified
2025-08-04 20:04:58,602 - aio_pika.robust_connection - INFO - Connection to  closed. Reconnecting after 5 seconds.
2025-08-04 20:04:58,602 - aio_pika.robust_connection - ERROR - Reconnect attempt failed . Retrying after 5 seconds.
Traceback (most recent call last):
  File "/home/data/freerad_api/.venv/lib/python3.13/site-packages/aio_pika/robust_connection.py", line 135, in __connection_factory
    await Connection.connect(self, self.__connect_timeout)
  File "/home/data/freerad_api/.venv/lib/python3.13/site-packages/aio_pika/connection.py", line 125, in connect
    self.transport = await UnderlayConnection.connect(
                     ^^^^^^^^^^^^^^^^^^^^^^^^^^^^^^^^^
    ...<2 lines>...
    )
    ^
  File "/home/data/freerad_api/.venv/lib/python3.13/site-packages/aio_pika/abc.py", line 679, in connect
    connection = await cls.make_connection(
                 ^^^^^^^^^^^^^^^^^^^^^^^^^^
        url, timeout=timeout, **kwargs,
        ^^^^^^^^^^^^^^^^^^^^^^^^^^^^^^^
    )
    ^
  File "/home/data/freerad_api/.venv/lib/python3.13/site-packages/aio_pika/abc.py", line 667, in make_connection
    connection: aiormq.abc.AbstractConnection = await asyncio.wait_for(
                                                ^^^^^^^^^^^^^^^^^^^^^^^
        aiormq.connect(url, **kwargs), timeout=timeout,
        ^^^^^^^^^^^^^^^^^^^^^^^^^^^^^^^^^^^^^^^^^^^^^^^
    )
    ^
  File "/root/.local/share/uv/python/cpython-3.13.5-linux-x86_64-gnu/lib/python3.13/asyncio/tasks.py", line 507, in wait_for
    return await fut
           ^^^^^^^^^
  File "/home/data/freerad_api/.venv/lib/python3.13/site-packages/aiormq/connection.py", line 920, in connect
    await connection.connect(client_properties or {})
  File "/home/data/freerad_api/.venv/lib/python3.13/site-packages/aiormq/base.py", line 164, in wrap
    return await self.create_task(func(self, *args, **kwargs))
           ^^^^^^^^^^^^^^^^^^^^^^^^^^^^^^^^^^^^^^^^^^^^^^^^^^^
  File "/home/data/freerad_api/.venv/lib/python3.13/site-packages/aiormq/abc.py", line 44, in __inner
    return await self.task
           ^^^^^^^^^^^^^^^
  File "/home/data/freerad_api/.venv/lib/python3.13/site-packages/aiormq/connection.py", line 457, in connect
    reader, writer = await asyncio.open_connection(
                     ^^^^^^^^^^^^^^^^^^^^^^^^^^^^^^
    ...<2 lines>...
    )
    ^
  File "/root/.local/share/uv/python/cpython-3.13.5-linux-x86_64-gnu/lib/python3.13/asyncio/streams.py", line 48, in open_connection
    transport, _ = await loop.create_connection(
                   ^^^^^^^^^^^^^^^^^^^^^^^^^^^^^
        lambda: protocol, host, port, **kwds)
        ^^^^^^^^^^^^^^^^^^^^^^^^^^^^^^^^^^^^^
  File "uvloop/loop.pyx", line 2050, in create_connection
ValueError: host and port was not specified and no sock specified
2025-08-04 20:05:03,604 - aio_pika.robust_connection - INFO - Connection to  closed. Reconnecting after 5 seconds.
2025-08-04 20:05:03,604 - aio_pika.robust_connection - ERROR - Reconnect attempt failed . Retrying after 5 seconds.
Traceback (most recent call last):
  File "/home/data/freerad_api/.venv/lib/python3.13/site-packages/aio_pika/robust_connection.py", line 135, in __connection_factory
    await Connection.connect(self, self.__connect_timeout)
  File "/home/data/freerad_api/.venv/lib/python3.13/site-packages/aio_pika/connection.py", line 125, in connect
    self.transport = await UnderlayConnection.connect(
                     ^^^^^^^^^^^^^^^^^^^^^^^^^^^^^^^^^
    ...<2 lines>...
    )
    ^
  File "/home/data/freerad_api/.venv/lib/python3.13/site-packages/aio_pika/abc.py", line 679, in connect
    connection = await cls.make_connection(
                 ^^^^^^^^^^^^^^^^^^^^^^^^^^
        url, timeout=timeout, **kwargs,
        ^^^^^^^^^^^^^^^^^^^^^^^^^^^^^^^
    )
    ^
  File "/home/data/freerad_api/.venv/lib/python3.13/site-packages/aio_pika/abc.py", line 667, in make_connection
    connection: aiormq.abc.AbstractConnection = await asyncio.wait_for(
                                                ^^^^^^^^^^^^^^^^^^^^^^^
        aiormq.connect(url, **kwargs), timeout=timeout,
        ^^^^^^^^^^^^^^^^^^^^^^^^^^^^^^^^^^^^^^^^^^^^^^^
    )
    ^
  File "/root/.local/share/uv/python/cpython-3.13.5-linux-x86_64-gnu/lib/python3.13/asyncio/tasks.py", line 507, in wait_for
    return await fut
           ^^^^^^^^^
  File "/home/data/freerad_api/.venv/lib/python3.13/site-packages/aiormq/connection.py", line 920, in connect
    await connection.connect(client_properties or {})
  File "/home/data/freerad_api/.venv/lib/python3.13/site-packages/aiormq/base.py", line 164, in wrap
    return await self.create_task(func(self, *args, **kwargs))
           ^^^^^^^^^^^^^^^^^^^^^^^^^^^^^^^^^^^^^^^^^^^^^^^^^^^
  File "/home/data/freerad_api/.venv/lib/python3.13/site-packages/aiormq/abc.py", line 44, in __inner
    return await self.task
           ^^^^^^^^^^^^^^^
  File "/home/data/freerad_api/.venv/lib/python3.13/site-packages/aiormq/connection.py", line 457, in connect
    reader, writer = await asyncio.open_connection(
                     ^^^^^^^^^^^^^^^^^^^^^^^^^^^^^^
    ...<2 lines>...
    )
    ^
  File "/root/.local/share/uv/python/cpython-3.13.5-linux-x86_64-gnu/lib/python3.13/asyncio/streams.py", line 48, in open_connection
    transport, _ = await loop.create_connection(
                   ^^^^^^^^^^^^^^^^^^^^^^^^^^^^^
        lambda: protocol, host, port, **kwds)
        ^^^^^^^^^^^^^^^^^^^^^^^^^^^^^^^^^^^^^
  File "uvloop/loop.pyx", line 2050, in create_connection
ValueError: host and port was not specified and no sock specified
2025-08-04 20:05:08,610 - aio_pika.robust_connection - INFO - Connection to  closed. Reconnecting after 5 seconds.
2025-08-04 20:05:08,610 - aio_pika.robust_connection - ERROR - Reconnect attempt failed . Retrying after 5 seconds.
Traceback (most recent call last):
  File "/home/data/freerad_api/.venv/lib/python3.13/site-packages/aio_pika/robust_connection.py", line 135, in __connection_factory
    await Connection.connect(self, self.__connect_timeout)
  File "/home/data/freerad_api/.venv/lib/python3.13/site-packages/aio_pika/connection.py", line 125, in connect
    self.transport = await UnderlayConnection.connect(
                     ^^^^^^^^^^^^^^^^^^^^^^^^^^^^^^^^^
    ...<2 lines>...
    )
    ^
  File "/home/data/freerad_api/.venv/lib/python3.13/site-packages/aio_pika/abc.py", line 679, in connect
    connection = await cls.make_connection(
                 ^^^^^^^^^^^^^^^^^^^^^^^^^^
        url, timeout=timeout, **kwargs,
        ^^^^^^^^^^^^^^^^^^^^^^^^^^^^^^^
    )
    ^
  File "/home/data/freerad_api/.venv/lib/python3.13/site-packages/aio_pika/abc.py", line 667, in make_connection
    connection: aiormq.abc.AbstractConnection = await asyncio.wait_for(
                                                ^^^^^^^^^^^^^^^^^^^^^^^
        aiormq.connect(url, **kwargs), timeout=timeout,
        ^^^^^^^^^^^^^^^^^^^^^^^^^^^^^^^^^^^^^^^^^^^^^^^
    )
    ^
  File "/root/.local/share/uv/python/cpython-3.13.5-linux-x86_64-gnu/lib/python3.13/asyncio/tasks.py", line 507, in wait_for
    return await fut
           ^^^^^^^^^
  File "/home/data/freerad_api/.venv/lib/python3.13/site-packages/aiormq/connection.py", line 920, in connect
    await connection.connect(client_properties or {})
  File "/home/data/freerad_api/.venv/lib/python3.13/site-packages/aiormq/base.py", line 164, in wrap
    return await self.create_task(func(self, *args, **kwargs))
           ^^^^^^^^^^^^^^^^^^^^^^^^^^^^^^^^^^^^^^^^^^^^^^^^^^^
  File "/home/data/freerad_api/.venv/lib/python3.13/site-packages/aiormq/abc.py", line 44, in __inner
    return await self.task
           ^^^^^^^^^^^^^^^
  File "/home/data/freerad_api/.venv/lib/python3.13/site-packages/aiormq/connection.py", line 457, in connect
    reader, writer = await asyncio.open_connection(
                     ^^^^^^^^^^^^^^^^^^^^^^^^^^^^^^
    ...<2 lines>...
    )
    ^
  File "/root/.local/share/uv/python/cpython-3.13.5-linux-x86_64-gnu/lib/python3.13/asyncio/streams.py", line 48, in open_connection
    transport, _ = await loop.create_connection(
                   ^^^^^^^^^^^^^^^^^^^^^^^^^^^^^
        lambda: protocol, host, port, **kwds)
        ^^^^^^^^^^^^^^^^^^^^^^^^^^^^^^^^^^^^^
  File "uvloop/loop.pyx", line 2050, in create_connection
ValueError: host and port was not specified and no sock specified
